Workbook
Name Slicer_Representative: #N/A
Name Slicer_Representative1: #N/A
Name Slicer_Representative2: #N/A

Sheet s9
A3: Count of Call number | B3: Column Labels
A4: Row Labels | B4: Jan | C4: Feb | D4: Mar | E4: Apr | F4: May | G4: Jun | H4: Jul | I4: Aug | J4: Sep | K4: Oct | L4: Nov | M4: Dec | N4: Grand Total
A5: R01 | B5: 16 | C5: 14 | D5: 26 | E5: 29 | F5: 17 | G5: 15 | H5: 15 | I5: 7 | J5: 11 | K5: 24 | L5: 9 | M5: 6 | N5: 189
A6: R02 | B6: 19 | C6: 10 | D6: 40 | E6: 40 | F6: 13 | G6: 12 | H6: 9 | I6: 13 | J6: 18 | K6: 21 | L6: 14 | M6: 9 | N6: 218
A7: R03 | B7: 13 | C7: 13 | D7: 28 | E7: 24 | F7: 23 | G7: 17 | H7: 11 | I7: 11 | J7: 14 | K7: 30 | L7: 14 | M7: 9 | N7: 207
A8: R04 | B8: 10 | C8: 11 | D8: 30 | E8: 23 | F8: 22 | G8: 11 | H8: 17 | I8: 12 | J8: 13 | K8: 15 | L8: 8 | M8: 14 | N8: 186
A9: R05 | B9: 21 | C9: 18 | D9: 31 | E9: 20 | F9: 8 | G9: 12 | H9: 12 | I9: 7 | J9: 20 | K9: 24 | L9: 12 | M9: 15 | N9: 200
A10: Grand Total | B10: 79 | C10: 66 | D10: 155 | E10: 136 | F10: 83 | G10: 67 | H10: 64 | I10: 50 | J10: 76 | K10: 114 | L10: 57 | M10: 53 | N10: 1000

Sheet Sheet9
A1: Data returned for Call cnt, R03 (First 1000 rows).
A3: calls[Call number] | B3: calls[Customer ID] | C3: calls[Duration] | D3: calls[Representative] | E3: calls[Date of Call] | F3: calls[Purchase Amount] | G3: calls[avg satisfication] | H3: calls[flag reps] | I3: calls[Satisfaction Rating] | J3: calls[FY] | K3: calls[Day of week] | L3: calls[Duration Bucket] | M3: calls[Rating rounded] | N3: calls[count no. of class per person] | O3: calls[Average purchase per call] | P3: calls["time wasters"column ratio] | Q3: calls[call count] | R3: calls[call to purchase ratio] | S3: calls[Date of Call (Month)] | T3: calls[Date of Call (Month Index)]
A4: Call_7280 | B4: C0010 | C4: 44 | D4: R03 | E4: 44929 | F4: 105 | G4: 3.8589372 | H4: OK | I4: 2.9 | J4: 2023 | K4: Tuesday | L4: 60 to 30mins | M4: 3 | N4: 72 | O4: 6242 | P4: 0.68571429 | Q4: 72 | R4: 0.68571429 | S4: Jan | T4: 1
A5: Call_7288 | B5: C0009 | C5: 28 | D5: R03 | E5: 44931 | F5: 28 | G5: 3.8589372 | H5: OK | I5: 3.8 | J5: 2023 | K5: Thursday | L5: 10 to 30mins | M5: 4 | N5: 69 | O5: 6601 | P5: 2.4642857 | Q5: 69 | R5: 2.4642857 | S5: Jan | T5: 1
A6: Call_7306 | B6: C0009 | C6: 75 | D6: R03 | E6: 44941 | F6: 26 | G6: 3.8589372 | H6: OK | I6: 2.4 | J6: 2023 | K6: Sunday | L6: 1 to 2hrs | M6: 2 | N6: 69 | O6: 6601 | P6: 2.6538462 | Q6: 69 | R6: 2.6538462 | S6: Jan | T6: 1
A7: Call_7307 | B7: C0015 | C7: 94 | D7: R03 | E7: 44942 | F7: 120 | G7: 3.8589372 | H7: OK | I7: 3.1 | J7: 2023 | K7: Monday | L7: 1 to 2hrs | M7: 3 | N7: 59 | O7: 6518 | P7: 0.49166667 | Q7: 59 | R7: 0.49166667 | S7: Jan | T7: 1
A8: Call_7314 | B8: C0013 | C8: 132 | D8: R03 | E8: 44944 | F8: 168 | G8: 3.8589372 | H8: OK | I8: 4.1 | J8: 2023 | K8: Wednesday | L8: More than 2 hrs | M8: 4 | N8: 69 | O8: 7230 | P8: 0.41071429 | Q8: 69 | R8: 0.41071429 | S8: Jan | T8: 1
A9: Call_7316 | B9: C0011 | C9: 9 | D9: R03 | E9: 44945 | F9: 32 | G9: 3.8589372 | H9: OK | I9: 4.4 | J9: 2023 | K9: Thursday | L9: under 10 mins | M9: 4 | N9: 74 | O9: 6749 | P9: 2.3125 | Q9: 74 | R9: 2.3125 | S9: Jan | T9: 1
A10: Call_7323 | B10: C0013 | C10: 79 | D10: R03 | E10: 44947 | F10: 140 | G10: 3.8589372 | H10: OK | I10: 4.5 | J10: 2023 | K10: Saturday | L10: 1 to 2hrs | M10: 5 | N10: 69 | O10: 7230 | P10: 0.49285714 | Q10: 69 | R10: 0.49285714 | S10: Jan | T10: 1
A11: Call_7333 | B11: C0015 | C11: 110 | D11: R03 | E11: 44950 | F11: 96 | G11: 3.8589372 | H11: OK | I11: 5 | J11: 2023 | K11: Tuesday | L11: 1 to 2hrs | M11: 5 | N11: 59 | O11: 6518 | P11: 0.61458333 | Q11: 59 | R11: 0.61458333 | S11: Jan | T11: 1
A12: Call_7340 | B12: C0006 | C12: 141 | D12: R03 | E12: 44953 | F12: 54 | G12: 3.8589372 | H12: OK | I12: 0 | J12: 2023 | K12: Friday | L12: More than 2 hrs | M12: 0 | N12: 62 | O12: 6176 | P12: 1.1481481 | Q12: 62 | R12: 1.1481481 | S12: Jan | T12: 1
A13: Call_7341 | B13: C0006 | C13: 168 | D13: R03 | E13: 44954 | F13: 160 | G13: 3.8589372 | H13: OK | I13: 3.9 | J13: 2023 | K13: Saturday | L13: More than 2 hrs | M13: 4 | N13: 62 | O13: 6176 | P13: 0.3875 | Q13: 62 | R13: 0.3875 | S13: Jan | T13: 1
A14: Call_7344 | B14: C0008 | C14: 114 | D14: R03 | E14: 44956 | F14: 42 | G14: 3.8589372 | H14: OK | I14: 2.6 | J14: 2023 | K14: Monday | L14: 1 to 2hrs | M14: 3 | N14: 59 | O14: 5009 | P14: 1.4047619 | Q14: 59 | R14: 1.4047619 | S14: Jan | T14: 1
A15: Call_7346 | B15: C0011 | C15: 69 | D15: R03 | E15: 44956 | F15: 108 | G15: 3.8589372 | H15: OK | I15: 3.3 | J15: 2023 | K15: Monday | L15: 1 to 2hrs | M15: 3 | N15: 74 | O15: 6749 | P15: 0.68518519 | Q15: 74 | R15: 0.68518519 | S15: Jan | T15: 1
... A210: Call_8261 | B210: C0005 | C210: 164 | D210: R03 | E210: 45289 | F210: 100 | G210: 3.8589372 | H210: OK | I210: 4.6 | J210: 2024 | K210: Friday | L210: More than 2 hrs | M210: 5 | N210: 79 | O210: 7747 | P210: 0.79 | Q210: 79 | R210: 0.79 | S210: Dec | T210: 12

Sheet Sheet10
A1: Data returned for Call cnt, R04 (First 1000 rows).
A3: calls[Call number] | B3: calls[Customer ID] | C3: calls[Duration] | D3: calls[Representative] | E3: calls[Date of Call] | F3: calls[Purchase Amount] | G3: calls[avg satisfication] | H3: calls[flag reps] | I3: calls[Satisfaction Rating] | J3: calls[FY] | K3: calls[Day of week] | L3: calls[Duration Bucket] | M3: calls[Rating rounded] | N3: calls[count no. of class per person] | O3: calls[Average purchase per call] | P3: calls["time wasters"column ratio] | Q3: calls[call count] | R3: calls[call to purchase ratio] | S3: calls[Date of Call (Month)] | T3: calls[Date of Call (Month Index)]
A4: Call_7278 | B4: C0003 | C4: 103 | D4: R04 | E4: 44929 | F4: 148 | G4: 3.8973118 | H4: OK | I4: 4.4 | J4: 2023 | K4: Tuesday | L4: 1 to 2hrs | M4: 4 | N4: 50 | O4: 4804 | P4: 0.33783784 | Q4: 50 | R4: 0.33783784 | S4: Jan | T4: 1
A5: Call_7292 | B5: C0004 | C5: 38 | D5: R04 | E5: 44933 | F5: 92 | G5: 3.8973118 | H5: OK | I5: 4.9 | J5: 2023 | K5: Saturday | L5: 60 to 30mins | M5: 5 | N5: 82 | O5: 7689 | P5: 0.89130435 | Q5: 82 | R5: 0.89130435 | S5: Jan | T5: 1
A6: Call_7293 | B6: C0003 | C6: 67 | D6: R04 | E6: 44934 | F6: 165 | G6: 3.8973118 | H6: OK | I6: 4.5 | J6: 2023 | K6: Sunday | L6: 1 to 2hrs | M6: 5 | N6: 50 | O6: 4804 | P6: 0.3030303 | Q6: 50 | R6: 0.3030303 | S6: Jan | T6: 1
A7: Call_7299 | B7: C0009 | C7: 31 | D7: R04 | E7: 44936 | F7: 123 | G7: 3.8973118 | H7: OK | I7: 2.9 | J7: 2023 | K7: Tuesday | L7: 60 to 30mins | M7: 3 | N7: 69 | O7: 6601 | P7: 0.56097561 | Q7: 69 | R7: 0.56097561 | S7: Jan | T7: 1
A8: Call_7309 | B8: C0015 | C8: 81 | D8: R04 | E8: 44943 | F8: 86 | G8: 3.8973118 | H8: OK | I8: 2.4 | J8: 2023 | K8: Tuesday | L8: 1 to 2hrs | M8: 2 | N8: 59 | O8: 6518 | P8: 0.68604651 | Q8: 59 | R8: 0.68604651 | S8: Jan | T8: 1
A9: Call_7311 | B9: C0004 | C9: 74 | D9: R04 | E9: 44943 | F9: 96 | G9: 3.8973118 | H9: OK | I9: 4.7 | J9: 2023 | K9: Tuesday | L9: 1 to 2hrs | M9: 5 | N9: 82 | O9: 7689 | P9: 0.85416667 | Q9: 82 | R9: 0.85416667 | S9: Jan | T9: 1
A10: Call_7322 | B10: C0013 | C10: 100 | D10: R04 | E10: 44947 | F10: 135 | G10: 3.8973118 | H10: OK | I10: 3.8 | J10: 2023 | K10: Saturday | L10: 1 to 2hrs | M10: 4 | N10: 69 | O10: 7230 | P10: 0.51111111 | Q10: 69 | R10: 0.51111111 | S10: Jan | T10: 1
A11: Call_7332 | B11: C0010 | C11: 130 | D11: R04 | E11: 44950 | F11: 126 | G11: 3.8973118 | H11: OK | I11: 2.5 | J11: 2023 | K11: Tuesday | L11: More than 2 hrs | M11: 3 | N11: 72 | O11: 6242 | P11: 0.57142857 | Q11: 72 | R11: 0.57142857 | S11: Jan | T11: 1
A12: Call_7335 | B12: C0001 | C12: 147 | D12: R04 | E12: 44951 | F12: 105 | G12: 3.8973118 | H12: OK | I12: 4.4 | J12: 2023 | K12: Wednesday | L12: More than 2 hrs | M12: 4 | N12: 65 | O12: 6785 | P12: 0.61904762 | Q12: 65 | R12: 0.61904762 | S12: Jan | T12: 1
A13: Call_7338 | B13: C0010 | C13: 124 | D13: R04 | E13: 44953 | F13: 215 | G13: 3.8973118 | H13: OK | I13: 4.1 | J13: 2023 | K13: Friday | L13: More than 2 hrs | M13: 4 | N13: 72 | O13: 6242 | P13: 0.33488372 | Q13: 72 | R13: 0.33488372 | S13: Jan | T13: 1
A14: Call_7351 | B14: C0010 | C14: 45 | D14: R04 | E14: 44958 | F14: 34 | G14: 3.8973118 | H14: OK | I14: 3.7 | J14: 2023 | K14: Wednesday | L14: 60 to 30mins | M14: 4 | N14: 72 | O14: 6242 | P14: 2.1176471 | Q14: 72 | R14: 2.1176471 | S14: Feb | T14: 2
A15: Call_7355 | B15: C0011 | C15: 137 | D15: R04 | E15: 44958 | F15: 90 | G15: 3.8973118 | H15: OK | I15: 4.1 | J15: 2023 | K15: Wednesday | L15: More than 2 hrs | M15: 4 | N15: 74 | O15: 6749 | P15: 0.82222222 | Q15: 74 | R15: 0.82222222 | S15: Feb | T15: 2
... A189: Call_8267 | B189: C0007 | C189: 127 | D189: R04 | E189: 45290 | F189: 215 | G189: 3.8973118 | H189: OK | I189: 3.8 | J189: 2024 | K189: Saturday | L189: More than 2 hrs | M189: 4 | N189: 67 | O189: 7216 | P189: 0.31162791 | Q189: 67 | R189: 0.31162791 | S189: Dec | T189: 12

Sheet Sheet11
A1: Data returned for TOT amt, R05 (First 1000 rows).
A3: calls[Call number] | B3: calls[Customer ID] | C3: calls[Duration] | D3: calls[Representative] | E3: calls[Date of Call] | F3: calls[Purchase Amount] | G3: calls[avg satisfication] | H3: calls[flag reps] | I3: calls[Satisfaction Rating] | J3: calls[FY] | K3: calls[Day of week] | L3: calls[Duration Bucket] | M3: calls[Rating rounded] | N3: calls[count no. of class per person] | O3: calls[Average purchase per call] | P3: calls["time wasters"column ratio] | Q3: calls[call count] | R3: calls[call to purchase ratio] | S3: calls[Date of Call (Month)] | T3: calls[Date of Call (Month Index)]
A4: Call_7271 | B4: C0003 | C4: 116 | D4: R05 | E4: 44927 | F4: 128 | G4: 3.8825 | H4: OK | I4: 4.9 | J4: 2023 | K4: Sunday | L4: 1 to 2hrs | M4: 5 | N4: 50 | O4: 4804 | P4: 0.390625 | Q4: 50 | R4: 0.390625 | S4: Jan | T4: 1
A5: Call_7272 | B5: C0004 | C5: 119 | D5: R05 | E5: 44927 | F5: 135 | G5: 3.8825 | H5: OK | I5: 2.9 | J5: 2023 | K5: Sunday | L5: 1 to 2hrs | M5: 3 | N5: 82 | O5: 7689 | P5: 0.60740741 | Q5: 82 | R5: 0.60740741 | S5: Jan | T5: 1
A6: Call_7277 | B6: C0007 | C6: 84 | D6: R05 | E6: 44929 | F6: 60 | G6: 3.8825 | H6: OK | I6: 4.7 | J6: 2023 | K6: Tuesday | L6: 1 to 2hrs | M6: 5 | N6: 67 | O6: 7216 | P6: 1.1166667 | Q6: 67 | R6: 1.1166667 | S6: Jan | T6: 1
A7: Call_7282 | B7: C0013 | C7: 135 | D7: R05 | E7: 44929 | F7: 46 | G7: 3.8825 | H7: OK | I7: 3.4 | J7: 2023 | K7: Tuesday | L7: More than 2 hrs | M7: 3 | N7: 69 | O7: 7230 | P7: 1.5 | Q7: 69 | R7: 1.5 | S7: Jan | T7: 1
A8: Call_7286 | B8: C0010 | C8: 176 | D8: R05 | E8: 44931 | F8: 24 | G8: 3.8825 | H8: OK | I8: 4.8 | J8: 2023 | K8: Thursday | L8: More than 2 hrs | M8: 5 | N8: 72 | O8: 6242 | P8: 3 | Q8: 72 | R8: 3 | S8: Jan | T8: 1
A9: Call_7290 | B9: C0006 | C9: 48 | D9: R05 | E9: 44932 | F9: 30 | G9: 3.8825 | H9: OK | I9: 4.4 | J9: 2023 | K9: Friday | L9: 60 to 30mins | M9: 4 | N9: 62 | O9: 6176 | P9: 2.0666667 | Q9: 62 | R9: 2.0666667 | S9: Jan | T9: 1
A10: Call_7291 | B10: C0004 | C10: 128 | D10: R05 | E10: 44932 | F10: 72 | G10: 3.8825 | H10: OK | I10: 5 | J10: 2023 | K10: Friday | L10: More than 2 hrs | M10: 5 | N10: 82 | O10: 7689 | P10: 1.1388889 | Q10: 82 | R10: 1.1388889 | S10: Jan | T10: 1
A11: Call_7296 | B11: C0012 | C11: 28 | D11: R05 | E11: 44935 | F11: 63 | G11: 3.8825 | H11: OK | I11: 4.1 | J11: 2023 | K11: Monday | L11: 10 to 30mins | M11: 4 | N11: 70 | O11: 6819 | P11: 1.1111111 | Q11: 70 | R11: 1.1111111 | S11: Jan | T11: 1
A12: Call_7297 | B12: C0002 | C12: 73 | D12: R05 | E12: 44935 | F12: 80 | G12: 3.8825 | H12: OK | I12: 4.2 | J12: 2023 | K12: Monday | L12: 1 to 2hrs | M12: 4 | N12: 63 | O12: 5634 | P12: 0.7875 | Q12: 63 | R12: 0.7875 | S12: Jan | T12: 1
A13: Call_7298 | B13: C0011 | C13: 81 | D13: R05 | E13: 44936 | F13: 50 | G13: 3.8825 | H13: OK | I13: 4.6 | J13: 2023 | K13: Tuesday | L13: 1 to 2hrs | M13: 5 | N13: 74 | O13: 6749 | P13: 1.48 | Q13: 74 | R13: 1.48 | S13: Jan | T13: 1
A14: Call_7301 | B14: C0009 | C14: 80 | D14: R05 | E14: 44936 | F14: 140 | G14: 3.8825 | H14: OK | I14: 4.2 | J14: 2023 | K14: Tuesday | L14: 1 to 2hrs | M14: 4 | N14: 69 | O14: 6601 | P14: 0.49285714 | Q14: 69 | R14: 0.49285714 | S14: Jan | T14: 1
A15: Call_7302 | B15: C0011 | C15: 82 | D15: R05 | E15: 44938 | F15: 42 | G15: 3.8825 | H15: OK | I15: 3.7 | J15: 2023 | K15: Thursday | L15: 1 to 2hrs | M15: 4 | N15: 74 | O15: 6749 | P15: 1.7619048 | Q15: 74 | R15: 1.7619048 | S15: Jan | T15: 1
... A203: Call_8269 | B203: C0010 | C203: 123 | D203: R05 | E203: 45291 | F203: 64 | G203: 3.8825 | H203: OK | I203: 3.7 | J203: 2024 | K203: Sunday | L203: More than 2 hrs | M203: 4 | N203: 72 | O203: 6242 | P203: 1.125 | Q203: 72 | R203: 1.125 | S203: Dec | T203: 12

Sheet Sheet1
A1: Data returned for Call cnt, 2, R01 (First 1000 rows).
A3: calls[Call number] | B3: calls[Customer ID] | C3: calls[Duration] | D3: calls[Representative] | E3: calls[Date of Call] | F3: calls[Purchase Amount] | G3: calls[avg satisfication] | H3: calls[flag reps] | I3: calls[Satisfaction Rating] | J3: calls[FY] | K3: calls[Day of week] | L3: calls[Duration Bucket] | M3: calls[Rating rounded] | N3: calls[count no. of class per person] | O3: calls[Average purchase per call] | P3: calls["time wasters"column ratio] | Q3: calls[call count] | R3: calls[call to purchase ratio] | S3: calls[Date of Call (Month)] | T3: calls[Date of Call (Month Index)]
A4: Call_7553 | B4: C0007 | C4: 61 | D4: R01 | E4: 45012 | F4: 140 | G4: 3.9227513 | H4: OK | I4: 1.8 | J4: 2023 | K4: Monday | L4: 1 to 2hrs | M4: 2 | N4: 67 | O4: 7216 | P4: 0.47857143 | Q4: 67 | R4: 0.47857143 | S4: Mar | T4: 3
A5: Call_7572 | B5: C0014 | C5: 42 | D5: R01 | E5: 45017 | F5: 45 | G5: 3.9227513 | H5: OK | I5: 1.5 | J5: 2023 | K5: Saturday | L5: 60 to 30mins | M5: 2 | N5: 60 | O5: 5404 | P5: 1.3333333 | Q5: 60 | R5: 1.3333333 | S5: Apr | T5: 4
A6: Call_7641 | B6: C0013 | C6: 69 | D6: R01 | E6: 45032 | F6: 130 | G6: 3.9227513 | H6: OK | I6: 1.9 | J6: 2023 | K6: Sunday | L6: 1 to 2hrs | M6: 2 | N6: 69 | O6: 7230 | P6: 0.53076923 | Q6: 69 | R6: 0.53076923 | S6: Apr | T6: 4
A7: Call_7903 | B7: C0014 | C7: 60 | D7: R01 | E7: 45128 | F7: 60 | G7: 3.9227513 | H7: OK | I7: 2.3 | J7: 2024 | K7: Friday | L7: 60 to 30mins | M7: 2 | N7: 60 | O7: 5404 | P7: 1 | Q7: 60 | R7: 1 | S7: Jul | T7: 7
A8: Call_7918 | B8: C0001 | C8: 33 | D8: R01 | E8: 45138 | F8: 92 | G8: 3.9227513 | H8: OK | I8: 1.7 | J8: 2024 | K8: Monday | L8: 60 to 30mins | M8: 2 | N8: 65 | O8: 6785 | P8: 0.70652174 | Q8: 65 | R8: 0.70652174 | S8: Jul | T8: 7
A9: Call_7946 | B9: C0011 | C9: 128 | D9: R01 | E9: 45157 | F9: 135 | G9: 3.9227513 | H9: OK | I9: 2.1 | J9: 2024 | K9: Saturday | L9: More than 2 hrs | M9: 2 | N9: 74 | O9: 6749 | P9: 0.54814815 | Q9: 74 | R9: 0.54814815 | S9: Aug | T9: 8
A10: Call_8147 | B10: C0014 | C10: 97 | D10: R01 | E10: 45226 | F10: 31 | G10: 3.9227513 | H10: OK | I10: 2.2 | J10: 2024 | K10: Friday | L10: 1 to 2hrs | M10: 2 | N10: 60 | O10: 5404 | P10: 1.9354839 | Q10: 60 | R10: 1.9354839 | S10: Oct | T10: 10
A11: Call_8150 | B11: C0013 | C11: 64 | D11: R01 | E11: 45227 | F11: 185 | G11: 3.9227513 | H11: OK | I11: 2.2 | J11: 2024 | K11: Saturday | L11: 1 to 2hrs | M11: 2 | N11: 69 | O11: 7230 | P11: 0.37297297 | Q11: 69 | R11: 0.37297297 | S11: Oct | T11: 10
A12: Call_8200 | B12: C0005 | C12: 50 | D12: R01 | E12: 45249 | F12: 180 | G12: 3.9227513 | H12: OK | I12: 1.8 | J12: 2024 | K12: Sunday | L12: 60 to 30mins | M12: 2 | N12: 79 | O12: 7747 | P12: 0.43888889 | Q12: 79 | R12: 0.43888889 | S12: Nov | T12: 11

Sheet pivots
A3: Call cnt | B3: TOT amt | C3: tot dur.. | D3: avg rating | E3: 5*call
A4: 1000 | B4: 96623 | C4: 89846 | D4: 3.8854 | E4: 307
A11: Call cnt | B11: TOT amt | C11: tot dur.. | D11: avg rating | E11: 5*call
A12: 207 | B12: 20872 | C12: 17696 | D12: 3.8589372 | E12: 60
A24: Row Labels | B24: Call cnt | C24: Call cnt2
A25: Jan | B25: 13 | C25: 13
A26: Feb | B26: 13 | C26: 13
A27: Mar | B27: 28 | C27: 28
A28: Apr | B28: 24 | C28: 24
A29: May | B29: 23 | C29: 23
A30: Jun | B30: 17 | C30: 17
A31: Jul | B31: 11 | C31: 11
A32: Aug | B32: 11 | C32: 11
A33: Sep | B33: 14 | C33: 14
A34: Oct | B34: 30 | C34: 30
A35: Nov | B35: 14 | C35: 14
A36: Dec | B36: 9 | C36: 9
A37: Grand Total | B37: 207 | C37: 207
A45: Row Labels | B45: Call cnt
A46: Sunday | B46: 30
A47: Monday | B47: 34
A48: Tuesday | B48: 26
A49: Wednesday | B49: 38
A50: Thursday | B50: 27
A51: Friday | B51: 27
A52: Saturday | B52: 25
A53: Grand Total | B53: 207
G59: for graph | J59: selected rep | K59: =A89 -> R03
G60: Rep | H60: Calls | I60: Amount | J60: sell calls | K60: sell amount
A61: Row Labels | B61: Call cnt | C61: TOT amt | G61: R01 | H61: 189 | I61: 18415 | J61: =IF(G61=K59,H61,NA()) -> #N/A | K61: =IF(G61=K59,I61,NA()) -> #N/A
A62: R01 | B62: 189 | C62: 18415 | G62: R02 | H62: 218 | I62: 20581 | J62: =IF(G62=K59,H62,NA()) -> #N/A | K62: =IF(G62=K59,I62,NA()) -> #N/A
A63: Grand Total | B63: 189 | C63: 18415 | G63: R03 | H63: 207 | I63: 20872 | J63: =IF(G63=K61,H63,NA()) -> #N/A | K63: =IF(G63=K59,I63,NA()) -> 20872
G64: R04 | H64: 186 | I64: 16651 | J64: =IF(G64=K59,H64,NA()) -> #N/A | K64: =IF(G64=K59,I64,NA()) -> #N/A
G65: R05 | H65: 200 | I65: 20104 | J65: =IF(G65=K59,H65,NA()) -> #N/A | K65: =IF(G65=K59,I65,NA()) -> #N/A
A88: Row Labels
A89: R03
A98: Call cnt | B98: Column Labels
A99: Row Labels | B99: Female | C99: Male | D99: Grand Total
A100: Cincinnati | B100: 144 | C100: 132 | D100: 276
A101: Cleveland | B101: 267 | C101: 63 | D101: 330
...

Sheet Sheet2
A1: Rep id | B1: Rep img
A2: R01
A3: R02
A4: R03
A5: R04
A6: R05

Sheet Data
A1: Call number | B1: Customer ID | C1: Duration | D1: Representative | E1: Date of Call | F1: Purchase Amount | G1: avg satisfication | H1: flag reps | I1: Satisfaction Rating | J1: FY | K1: Day of week | L1: Duration Bucket | M1: Rating rounded | N1: count no. of class per person | O1: Average purchase per call | P1: "time wasters"column ratio | Q1: call count | R1: call to purchase ratio
A2: Call_7271 | B2: C0003 | C2: 116 | D2: R05 | E2: 44927 | F2: 128 | G2: =AVERAGEIF(calls[Representative], calls[[#This Row],[Representative]], calls[Satisfaction Rating]) -> 3.8825 | H2: =IF(AVERAGEIF(calls[Representative],calls[[#This Row],[Representative]],calls[Satisfaction Rating])<3.5,"Needs Training","OK") -> OK | I2: 4.9 | J2: =IF(MONTH(calls[[#This Row],[Date of Call]])<=6, YEAR(calls[[#This Row],[Date of Call]]), YEAR(calls[[#This Row],[Date of Call]])+1) -> 2023 | K2: =TEXT(calls[[#This Row],[Date of Call]],"DDDD") -> Sunday | L2: {=_xlfn.IFS(calls[[#This Row],[Duration]]<=10,"under 10 mins",calls[[#This Row],[Duration]]<=30,"10 to 30mins",calls[[#This Row],[Duration]]<=60,"60 to 30mins",calls[[#This Row],[Duration]]<=120,"1 to 2hrs",TRUE,"More than 2 hrs")} -> 1 to 2hrs | M2: =ROUND(calls[[#This Row],[Satisfaction Rating]],0) -> 5 | N2: =COUNTIF(calls[Customer ID], calls[[#This Row],[Customer ID]]) -> 50 | O2: =SUMIF(calls[Customer ID], calls[[#This Row],[Customer ID]], calls[Purchase Amount]) -> 4804 | P2: =calls[[#This Row],[call count]]/calls[[#This Row],[Purchase Amount]] -> 0.390625 | Q2: =COUNTIF(calls[Customer ID],calls[[#This Row],[Customer ID]]) -> 50 | R2: =calls[[#This Row],[call count]]/calls[[#This Row],[Purchase Amount]] -> 0.390625
A3: Call_7272 | B3: C0004 | C3: 119 | D3: R05 | E3: 44927 | F3: 135 | G3: =AVERAGEIF(calls[Representative], calls[[#This Row],[Representative]], calls[Satisfaction Rating]) -> 3.8825 | H3: =IF(AVERAGEIF(calls[Representative],calls[[#This Row],[Representative]],calls[Satisfaction Rating])<3.5,"Needs Training","OK") -> OK | I3: 2.9 | J3: =IF(MONTH(calls[[#This Row],[Date of Call]])<=6, YEAR(calls[[#This Row],[Date of Call]]), YEAR(calls[[#This Row],[Date of Call]])+1) -> 2023 | K3: =TEXT(calls[[#This Row],[Date of Call]],"DDDD") -> Sunday | L3: {=_xlfn.IFS(calls[[#This Row],[Duration]]<=10,"under 10 mins",calls[[#This Row],[Duration]]<=30,"10 to 30mins",calls[[#This Row],[Duration]]<=60,"60 to 30mins",calls[[#This Row],[Duration]]<=120,"1 to 2hrs",TRUE,"More than 2 hrs")} -> 1 to 2hrs | M3: =ROUND(calls[[#This Row],[Satisfaction Rating]],0) -> 3 | N3: =COUNTIF(calls[Customer ID], calls[[#This Row],[Customer ID]]) -> 82 | O3: =SUMIF(calls[Customer ID], calls[[#This Row],[Customer ID]], calls[Purchase Amount]) -> 7689 | P3: =calls[[#This Row],[call count]]/calls[[#This Row],[Purchase Amount]] -> 0.60740741 | Q3: =COUNTIF(calls[Customer ID],calls[[#This Row],[Customer ID]]) -> 82 | R3: =calls[[#This Row],[call count]]/calls[[#This Row],[Purchase Amount]] -> 0.60740741
A4: Call_7273 | B4: C0005 | C4: 68 | D4: R02 | E4: 44927 | F4: 66 | G4: =AVERAGEIF(calls[Representative], calls[[#This Row],[Representative]], calls[Satisfaction Rating]) -> 3.8706422 | H4: =IF(AVERAGEIF(calls[Representative],calls[[#This Row],[Representative]],calls[Satisfaction Rating])<3.5,"Needs Training","OK") -> OK | I4: 4.7 | J4: =IF(MONTH(calls[[#This Row],[Date of Call]])<=6, YEAR(calls[[#This Row],[Date of Call]]), YEAR(calls[[#This Row],[Date of Call]])+1) -> 2023 | K4: =TEXT(calls[[#This Row],[Date of Call]],"DDDD") -> Sunday | L4: {=_xlfn.IFS(calls[[#This Row],[Duration]]<=10,"under 10 mins",calls[[#This Row],[Duration]]<=30,"10 to 30mins",calls[[#This Row],[Duration]]<=60,"60 to 30mins",calls[[#This Row],[Duration]]<=120,"1 to 2hrs",TRUE,"More than 2 hrs")} -> 1 to 2hrs | M4: =ROUND(calls[[#This Row],[Satisfaction Rating]],0) -> 5 | N4: =COUNTIF(calls[Customer ID], calls[[#This Row],[Customer ID]]) -> 79 | O4: =SUMIF(calls[Customer ID], calls[[#This Row],[Customer ID]], calls[Purchase Amount]) -> 7747 | P4: =calls[[#This Row],[call count]]/calls[[#This Row],[Purchase Amount]] -> 1.1969697 | Q4: =COUNTIF(calls[Customer ID],calls[[#This Row],[Customer ID]]) -> 79 | R4: =calls[[#This Row],[call count]]/calls[[#This Row],[Purchase Amount]] -> 1.1969697
A5: Call_7274 | B5: C0014 | C5: 119 | D5: R02 | E5: 44927 | F5: 22 | G5: =AVERAGEIF(calls[Representative], calls[[#This Row],[Representative]], calls[Satisfaction Rating]) -> 3.8706422 | H5: =IF(AVERAGEIF(calls[Representative],calls[[#This Row],[Representative]],calls[Satisfaction Rating])<3.5,"Needs Training","OK") -> OK | I5: 2.9 | J5: =IF(MONTH(calls[[#This Row],[Date of Call]])<=6, YEAR(calls[[#This Row],[Date of Call]]), YEAR(calls[[#This Row],[Date of Call]])+1) -> 2023 | K5: =TEXT(calls[[#This Row],[Date of Call]],"DDDD") -> Sunday | L5: {=_xlfn.IFS(calls[[#This Row],[Duration]]<=10,"under 10 mins",calls[[#This Row],[Duration]]<=30,"10 to 30mins",calls[[#This Row],[Duration]]<=60,"60 to 30mins",calls[[#This Row],[Duration]]<=120,"1 to 2hrs",TRUE,"More than 2 hrs")} -> 1 to 2hrs | M5: =ROUND(calls[[#This Row],[Satisfaction Rating]],0) -> 3 | N5: =COUNTIF(calls[Customer ID], calls[[#This Row],[Customer ID]]) -> 60 | O5: =SUMIF(calls[Customer ID], calls[[#This Row],[Customer ID]], calls[Purchase Amount]) -> 5404 | P5: =calls[[#This Row],[call count]]/calls[[#This Row],[Purchase Amount]] -> 2.7272727 | Q5: =COUNTIF(calls[Customer ID],calls[[#This Row],[Customer ID]]) -> 60 | R5: =calls[[#This Row],[call count]]/calls[[#This Row],[Purchase Amount]] -> 2.7272727
A6: Call_7275 | B6: C0011 | C6: 128 | D6: R01 | E6: 44928 | F6: 31 | G6: =AVERAGEIF(calls[Representative], calls[[#This Row],[Representative]], calls[Satisfaction Rating]) -> 3.9227513 | H6: =IF(AVERAGEIF(calls[Representative],calls[[#This Row],[Representative]],calls[Satisfaction Rating])<3.5,"Needs Training","OK") -> OK | I6: 2.8 | J6: =IF(MONTH(calls[[#This Row],[Date of Call]])<=6, YEAR(calls[[#This Row],[Date of Call]]), YEAR(calls[[#This Row],[Date of Call]])+1) -> 2023 | K6: =TEXT(calls[[#This Row],[Date of Call]],"DDDD") -> Monday | L6: {=_xlfn.IFS(calls[[#This Row],[Duration]]<=10,"under 10 mins",calls[[#This Row],[Duration]]<=30,"10 to 30mins",calls[[#This Row],[Duration]]<=60,"60 to 30mins",calls[[#This Row],[Duration]]<=120,"1 to 2hrs",TRUE,"More than 2 hrs")} -> More than 2 hrs | M6: =ROUND(calls[[#This Row],[Satisfaction Rating]],0) -> 3 | N6: =COUNTIF(calls[Customer ID], calls[[#This Row],[Customer ID]]) -> 74 | O6: =SUMIF(calls[Customer ID], calls[[#This Row],[Customer ID]], calls[Purchase Amount]) -> 6749 | P6: =calls[[#This Row],[call count]]/calls[[#This Row],[Purchase Amount]] -> 2.3870968 | Q6: =COUNTIF(calls[Customer ID],calls[[#This Row],[Customer ID]]) -> 74 | R6: =calls[[#This Row],[call count]]/calls[[#This Row],[Purchase Amount]] -> 2.3870968
A7: Call_7276 | B7: C0011 | C7: 49 | D7: R02 | E7: 44929 | F7: 135 | G7: =AVERAGEIF(calls[Representative], calls[[#This Row],[Representative]], calls[Satisfaction Rating]) -> 3.8706422 | H7: =IF(AVERAGEIF(calls[Representative],calls[[#This Row],[Representative]],calls[Satisfaction Rating])<3.5,"Needs Training","OK") -> OK | I7: 4.8 | J7: =IF(MONTH(calls[[#This Row],[Date of Call]])<=6, YEAR(calls[[#This Row],[Date of Call]]), YEAR(calls[[#This Row],[Date of Call]])+1) -> 2023 | K7: =TEXT(calls[[#This Row],[Date of Call]],"DDDD") -> Tuesday | L7: {=_xlfn.IFS(calls[[#This Row],[Duration]]<=10,"under 10 mins",calls[[#This Row],[Duration]]<=30,"10 to 30mins",calls[[#This Row],[Duration]]<=60,"60 to 30mins",calls[[#This Row],[Duration]]<=120,"1 to 2hrs",TRUE,"More than 2 hrs")} -> 60 to 30mins | M7: =ROUND(calls[[#This Row],[Satisfaction Rating]],0) -> 5 | N7: =COUNTIF(calls[Customer ID], calls[[#This Row],[Customer ID]]) -> 74 | O7: =SUMIF(calls[Customer ID], calls[[#This Row],[Customer ID]], calls[Purchase Amount]) -> 6749 | P7: =calls[[#This Row],[call count]]/calls[[#This Row],[Purchase Amount]] -> 0.54814815 | Q7: =COUNTIF(calls[Customer ID],calls[[#This Row],[Customer ID]]) -> 74 | R7: =calls[[#This Row],[call count]]/calls[[#This Row],[Purchase Amount]] -> 0.54814815 | W7: Customer ID | X7: Gedner | Y7: Age | Z7: City
A8: Call_7277 | B8: C0007 | C8: 84 | D8: R05 | E8: 44929 | F8: 60 | G8: =AVERAGEIF(calls[Representative], calls[[#This Row],[Representative]], calls[Satisfaction Rating]) -> 3.8825 | H8: =IF(AVERAGEIF(calls[Representative],calls[[#This Row],[Representative]],calls[Satisfaction Rating])<3.5,"Needs Training","OK") -> OK | I8: 4.7 | J8: =IF(MONTH(calls[[#This Row],[Date of Call]])<=6, YEAR(calls[[#This Row],[Date of Call]]), YEAR(calls[[#This Row],[Date of Call]])+1) -> 2023 | K8: =TEXT(calls[[#This Row],[Date of Call]],"DDDD") -> Tuesday | L8: {=_xlfn.IFS(calls[[#This Row],[Duration]]<=10,"under 10 mins",calls[[#This Row],[Duration]]<=30,"10 to 30mins",calls[[#This Row],[Duration]]<=60,"60 to 30mins",calls[[#This Row],[Duration]]<=120,"1 to 2hrs",TRUE,"More than 2 hrs")} -> 1 to 2hrs | M8: =ROUND(calls[[#This Row],[Satisfaction Rating]],0) -> 5 | N8: =COUNTIF(calls[Customer ID], calls[[#This Row],[Customer ID]]) -> 67 | O8: =SUMIF(calls[Customer ID], calls[[#This Row],[Customer ID]], calls[Purchase Amount]) -> 7216 | P8: =calls[[#This Row],[call count]]/calls[[#This Row],[Purchase Amount]] -> 1.1166667 | Q8: =COUNTIF(calls[Customer ID],calls[[#This Row],[Customer ID]]) -> 67 | R8: =calls[[#This Row],[call count]]/calls[[#This Row],[Purchase Amount]] -> 1.1166667 | W8: C0001 | X8: Male | Y8: 41 | Z8: Columbus
A9: Call_7278 | B9: C0003 | C9: 103 | D9: R04 | E9: 44929 | F9: 148 | G9: =AVERAGEIF(calls[Representative], calls[[#This Row],[Representative]], calls[Satisfaction Rating]) -> 3.8973118 | H9: =IF(AVERAGEIF(calls[Representative],calls[[#This Row],[Representative]],calls[Satisfaction Rating])<3.5,"Needs Training","OK") -> OK | I9: 4.4 | J9: =IF(MONTH(calls[[#This Row],[Date of Call]])<=6, YEAR(calls[[#This Row],[Date of Call]]), YEAR(calls[[#This Row],[Date of Call]])+1) -> 2023 | K9: =TEXT(calls[[#This Row],[Date of Call]],"DDDD") -> Tuesday | L9: {=_xlfn.IFS(calls[[#This Row],[Duration]]<=10,"under 10 mins",calls[[#This Row],[Duration]]<=30,"10 to 30mins",calls[[#This Row],[Duration]]<=60,"60 to 30mins",calls[[#This Row],[Duration]]<=120,"1 to 2hrs",TRUE,"More than 2 hrs")} -> 1 to 2hrs | M9: =ROUND(calls[[#This Row],[Satisfaction Rating]],0) -> 4 | N9: =COUNTIF(calls[Customer ID], calls[[#This Row],[Customer ID]]) -> 50 | O9: =SUMIF(calls[Customer ID], calls[[#This Row],[Customer ID]], calls[Purchase Amount]) -> 4804 | P9: =calls[[#This Row],[call count]]/calls[[#This Row],[Purchase Amount]] -> 0.33783784 | Q9: =COUNTIF(calls[Customer ID],calls[[#This Row],[Customer ID]]) -> 50 | R9: =calls[[#This Row],[call count]]/calls[[#This Row],[Purchase Amount]] -> 0.33783784 | W9: C0002 | X9: Male | Y9: 31 | Z9: Cleveland
A10: Call_7279 | B10: C0005 | C10: 31 | D10: R02 | E10: 44929 | F10: 135 | G10: =AVERAGEIF(calls[Representative], calls[[#This Row],[Representative]], calls[Satisfaction Rating]) -> 3.8706422 | H10: =IF(AVERAGEIF(calls[Representative],calls[[#This Row],[Representative]],calls[Satisfaction Rating])<3.5,"Needs Training","OK") -> OK | I10: 3.6 | J10: =IF(MONTH(calls[[#This Row],[Date of Call]])<=6, YEAR(calls[[#This Row],[Date of Call]]), YEAR(calls[[#This Row],[Date of Call]])+1) -> 2023 | K10: =TEXT(calls[[#This Row],[Date of Call]],"DDDD") -> Tuesday | L10: {=_xlfn.IFS(calls[[#This Row],[Duration]]<=10,"under 10 mins",calls[[#This Row],[Duration]]<=30,"10 to 30mins",calls[[#This Row],[Duration]]<=60,"60 to 30mins",calls[[#This Row],[Duration]]<=120,"1 to 2hrs",TRUE,"More than 2 hrs")} -> 60 to 30mins | M10: =ROUND(calls[[#This Row],[Satisfaction Rating]],0) -> 4 | N10: =COUNTIF(calls[Customer ID], calls[[#This Row],[Customer ID]]) -> 79 | O10: =SUMIF(calls[Customer ID], calls[[#This Row],[Customer ID]], calls[Purchase Amount]) -> 7747 | P10: =calls[[#This Row],[call count]]/calls[[#This Row],[Purchase Amount]] -> 0.58518519 | Q10: =COUNTIF(calls[Customer ID],calls[[#This Row],[Customer ID]]) -> 79 | R10: =calls[[#This Row],[call count]]/calls[[#This Row],[Purchase Amount]] -> 0.58518519 | W10: C0003 | X10: Male | Y10: 26 | Z10: Cincinnati
A11: Call_7280 | B11: C0010 | C11: 44 | D11: R03 | E11: 44929 | F11: 105 | G11: =AVERAGEIF(calls[Representative], calls[[#This Row],[Representative]], calls[Satisfaction Rating]) -> 3.8589372 | H11: =IF(AVERAGEIF(calls[Representative],calls[[#This Row],[Representative]],calls[Satisfaction Rating])<3.5,"Needs Training","OK") -> OK | I11: 2.9 | J11: =IF(MONTH(calls[[#This Row],[Date of Call]])<=6, YEAR(calls[[#This Row],[Date of Call]]), YEAR(calls[[#This Row],[Date of Call]])+1) -> 2023 | K11: =TEXT(calls[[#This Row],[Date of Call]],"DDDD") -> Tuesday | L11: {=_xlfn.IFS(calls[[#This Row],[Duration]]<=10,"under 10 mins",calls[[#This Row],[Duration]]<=30,"10 to 30mins",calls[[#This Row],[Duration]]<=60,"60 to 30mins",calls[[#This Row],[Duration]]<=120,"1 to 2hrs",TRUE,"More than 2 hrs")} -> 60 to 30mins | M11: =ROUND(calls[[#This Row],[Satisfaction Rating]],0) -> 3 | N11: =COUNTIF(calls[Customer ID], calls[[#This Row],[Customer ID]]) -> 72 | O11: =SUMIF(calls[Customer ID], calls[[#This Row],[Customer ID]], calls[Purchase Amount]) -> 6242 | P11: =calls[[#This Row],[call count]]/calls[[#This Row],[Purchase Amount]] -> 0.68571429 | Q11: =COUNTIF(calls[Customer ID],calls[[#This Row],[Customer ID]]) -> 72 | R11: =calls[[#This Row],[call count]]/calls[[#This Row],[Purchase Amount]] -> 0.68571429 | W11: C0004 | X11: Male | Y11: 36 | Z11: Cincinnati
A12: Call_7281 | B12: C0011 | C12: 102 | D12: R02 | E12: 44929 | F12: 69 | G12: =AVERAGEIF(calls[Representative], calls[[#This Row],[Representative]], calls[Satisfaction Rating]) -> 3.8706422 | H12: =IF(AVERAGEIF(calls[Representative],calls[[#This Row],[Representative]],calls[Satisfaction Rating])<3.5,"Needs Training","OK") -> OK | I12: 4.9 | J12: =IF(MONTH(calls[[#This Row],[Date of Call]])<=6, YEAR(calls[[#This Row],[Date of Call]]), YEAR(calls[[#This Row],[Date of Call]])+1) -> 2023 | K12: =TEXT(calls[[#This Row],[Date of Call]],"DDDD") -> Tuesday | L12: {=_xlfn.IFS(calls[[#This Row],[Duration]]<=10,"under 10 mins",calls[[#This Row],[Duration]]<=30,"10 to 30mins",calls[[#This Row],[Duration]]<=60,"60 to 30mins",calls[[#This Row],[Duration]]<=120,"1 to 2hrs",TRUE,"More than 2 hrs")} -> 1 to 2hrs | M12: =ROUND(calls[[#This Row],[Satisfaction Rating]],0) -> 5 | N12: =COUNTIF(calls[Customer ID], calls[[#This Row],[Customer ID]]) -> 74 | O12: =SUMIF(calls[Customer ID], calls[[#This Row],[Customer ID]], calls[Purchase Amount]) -> 6749 | P12: =calls[[#This Row],[call count]]/calls[[#This Row],[Purchase Amount]] -> 1.0724638 | Q12: =COUNTIF(calls[Customer ID],calls[[#This Row],[Customer ID]]) -> 74 | R12: =calls[[#This Row],[call count]]/calls[[#This Row],[Purchase Amount]] -> 1.0724638 | W12: C0005 | X12: Male | Y12: 37 | Z12: Columbus
A13: Call_7282 | B13: C0013 | C13: 135 | D13: R05 | E13: 44929 | F13: 46 | G13: =AVERAGEIF(calls[Representative], calls[[#This Row],[Representative]], calls[Satisfaction Rating]) -> 3.8825 | H13: =IF(AVERAGEIF(calls[Representative],calls[[#This Row],[Representative]],calls[Satisfaction Rating])<3.5,"Needs Training","OK") -> OK | I13: 3.4 | J13: =IF(MONTH(calls[[#This Row],[Date of Call]])<=6, YEAR(calls[[#This Row],[Date of Call]]), YEAR(calls[[#This Row],[Date of Call]])+1) -> 2023 | K13: =TEXT(calls[[#This Row],[Date of Call]],"DDDD") -> Tuesday | L13: {=_xlfn.IFS(calls[[#This Row],[Duration]]<=10,"under 10 mins",calls[[#This Row],[Duration]]<=30,"10 to 30mins",calls[[#This Row],[Duration]]<=60,"60 to 30mins",calls[[#This Row],[Duration]]<=120,"1 to 2hrs",TRUE,"More than 2 hrs")} -> More than 2 hrs | M13: =ROUND(calls[[#This Row],[Satisfaction Rating]],0) -> 3 | N13: =COUNTIF(calls[Customer ID], calls[[#This Row],[Customer ID]]) -> 69 | O13: =SUMIF(calls[Customer ID], calls[[#This Row],[Customer ID]], calls[Purchase Amount]) -> 7230 | P13: =calls[[#This Row],[call count]]/calls[[#This Row],[Purchase Amount]] -> 1.5 | Q13: =COUNTIF(calls[Customer ID],calls[[#This Row],[Customer ID]]) -> 69 | R13: =calls[[#This Row],[call count]]/calls[[#This Row],[Purchase Amount]] -> 1.5 | W13: C0006 | X13: Male | Y13: 23 | Z13: Columbus
A14: Call_7283 | B14: C0002 | C14: 98 | D14: R02 | E14: 44930 | F14: 108 | G14: =AVERAGEIF(calls[Representative], calls[[#This Row],[Representative]], calls[Satisfaction Rating]) -> 3.8706422 | H14: =IF(AVERAGEIF(calls[Representative],calls[[#This Row],[Representative]],calls[Satisfaction Rating])<3.5,"Needs Training","OK") -> OK | I14: 3.5 | J14: =IF(MONTH(calls[[#This Row],[Date of Call]])<=6, YEAR(calls[[#This Row],[Date of Call]]), YEAR(calls[[#This Row],[Date of Call]])+1) -> 2023 | K14: =TEXT(calls[[#This Row],[Date of Call]],"DDDD") -> Wednesday | L14: {=_xlfn.IFS(calls[[#This Row],[Duration]]<=10,"under 10 mins",calls[[#This Row],[Duration]]<=30,"10 to 30mins",calls[[#This Row],[Duration]]<=60,"60 to 30mins",calls[[#This Row],[Duration]]<=120,"1 to 2hrs",TRUE,"More than 2 hrs")} -> 1 to 2hrs | M14: =ROUND(calls[[#This Row],[Satisfaction Rating]],0) -> 4 | N14: =COUNTIF(calls[Customer ID], calls[[#This Row],[Customer ID]]) -> 63 | O14: =SUMIF(calls[Customer ID], calls[[#This Row],[Customer ID]], calls[Purchase Amount]) -> 5634 | P14: =calls[[#This Row],[call count]]/calls[[#This Row],[Purchase Amount]] -> 0.58333333 | Q14: =COUNTIF(calls[Customer ID],calls[[#This Row],[Customer ID]]) -> 63 | R14: =calls[[#This Row],[call count]]/calls[[#This Row],[Purchase Amount]] -> 0.58333333 | W14: C0007 | X14: Female | Y14: 22 | Z14: Cleveland
A15: Call_7284 | B15: C0010 | C15: 139 | D15: R02 | E15: 44930 | F15: 96 | G15: =AVERAGEIF(calls[Representative], calls[[#This Row],[Representative]], calls[Satisfaction Rating]) -> 3.8706422 | H15: =IF(AVERAGEIF(calls[Representative],calls[[#This Row],[Representative]],calls[Satisfaction Rating])<3.5,"Needs Training","OK") -> OK | I15: 4 | J15: =IF(MONTH(calls[[#This Row],[Date of Call]])<=6, YEAR(calls[[#This Row],[Date of Call]]), YEAR(calls[[#This Row],[Date of Call]])+1) -> 2023 | K15: =TEXT(calls[[#This Row],[Date of Call]],"DDDD") -> Wednesday | L15: {=_xlfn.IFS(calls[[#This Row],[Duration]]<=10,"under 10 mins",calls[[#This Row],[Duration]]<=30,"10 to 30mins",calls[[#This Row],[Duration]]<=60,"60 to 30mins",calls[[#This Row],[Duration]]<=120,"1 to 2hrs",TRUE,"More than 2 hrs")} -> More than 2 hrs | M15: =ROUND(calls[[#This Row],[Satisfaction Rating]],0) -> 4 | N15: =COUNTIF(calls[Customer ID], calls[[#This Row],[Customer ID]]) -> 72 | O15: =SUMIF(calls[Customer ID], calls[[#This Row],[Customer ID]], calls[Purchase Amount]) -> 6242 | P15: =calls[[#This Row],[call count]]/calls[[#This Row],[Purchase Amount]] -> 0.75 | Q15: =COUNTIF(calls[Customer ID],calls[[#This Row],[Customer ID]]) -> 72 | R15: =calls[[#This Row],[call count]]/calls[[#This Row],[Purchase Amount]] -> 0.75 | W15: C0008 | X15: Female | Y15: 42 | Z15: Cleveland
A16: Call_7285 | B16: C0013 | C16: 48 | D16: R01 | E16: 44930 | F16: 68 | G16: =AVERAGEIF(calls[Representative], calls[[#This Row],[Representative]], calls[Satisfaction Rating]) -> 3.9227513 | H16: =IF(AVERAGEIF(calls[Representative],calls[[#This Row],[Representative]],calls[Satisfaction Rating])<3.5,"Needs Training","OK") -> OK | I16: 4.9 | J16: =IF(MONTH(calls[[#This Row],[Date of Call]])<=6, YEAR(calls[[#This Row],[Date of Call]]), YEAR(calls[[#This Row],[Date of Call]])+1) -> 2023 | K16: =TEXT(calls[[#This Row],[Date of Call]],"DDDD") -> Wednesday | L16: {=_xlfn.IFS(calls[[#This Row],[Duration]]<=10,"under 10 mins",calls[[#This Row],[Duration]]<=30,"10 to 30mins",calls[[#This Row],[Duration]]<=60,"60 to 30mins",calls[[#This Row],[Duration]]<=120,"1 to 2hrs",TRUE,"More than 2 hrs")} -> 60 to 30mins | M16: =ROUND(calls[[#This Row],[Satisfaction Rating]],0) -> 5 | N16: =COUNTIF(calls[Customer ID], calls[[#This Row],[Customer ID]]) -> 69 | O16: =SUMIF(calls[Customer ID], calls[[#This Row],[Customer ID]], calls[Purchase Amount]) -> 7230 | P16: =calls[[#This Row],[call count]]/calls[[#This Row],[Purchase Amount]] -> 1.0147059 | Q16: =COUNTIF(calls[Customer ID],calls[[#This Row],[Customer ID]]) -> 69 | R16: =calls[[#This Row],[call count]]/calls[[#This Row],[Purchase Amount]] -> 1.0147059 | W16: C0009 | X16: Female | Y16: 25 | Z16: Columbus
A17: Call_7286 | B17: C0010 | C17: 176 | D17: R05 | E17: 44931 | F17: 24 | G17: =AVERAGEIF(calls[Representative], calls[[#This Row],[Representative]], calls[Satisfaction Rating]) -> 3.8825 | H17: =IF(AVERAGEIF(calls[Representative],calls[[#This Row],[Representative]],calls[Satisfaction Rating])<3.5,"Needs Training","OK") -> OK | I17: 4.8 | J17: =IF(MONTH(calls[[#This Row],[Date of Call]])<=6, YEAR(calls[[#This Row],[Date of Call]]), YEAR(calls[[#This Row],[Date of Call]])+1) -> 2023 | K17: =TEXT(calls[[#This Row],[Date of Call]],"DDDD") -> Thursday | L17: {=_xlfn.IFS(calls[[#This Row],[Duration]]<=10,"under 10 mins",calls[[#This Row],[Duration]]<=30,"10 to 30mins",calls[[#This Row],[Duration]]<=60,"60 to 30mins",calls[[#This Row],[Duration]]<=120,"1 to 2hrs",TRUE,"More than 2 hrs")} -> More than 2 hrs | M17: =ROUND(calls[[#This Row],[Satisfaction Rating]],0) -> 5 | N17: =COUNTIF(calls[Customer ID], calls[[#This Row],[Customer ID]]) -> 72 | O17: =SUMIF(calls[Customer ID], calls[[#This Row],[Customer ID]], calls[Purchase Amount]) -> 6242 | P17: =calls[[#This Row],[call count]]/calls[[#This Row],[Purchase Amount]] -> 3 | Q17: =COUNTIF(calls[Customer ID],calls[[#This Row],[Customer ID]]) -> 72 | R17: =calls[[#This Row],[call count]]/calls[[#This Row],[Purchase Amount]] -> 3 | W17: C0010 | X17: Female | Y17: 30 | Z17: Cleveland
A18: Call_7287 | B18: C0010 | C18: 99 | D18: R01 | E18: 44931 | F18: 195 | G18: =AVERAGEIF(calls[Representative], calls[[#This Row],[Representative]], calls[Satisfaction Rating]) -> 3.9227513 | H18: =IF(AVERAGEIF(calls[Representative],calls[[#This Row],[Representative]],calls[Satisfaction Rating])<3.5,"Needs Training","OK") -> OK | I18: 3.9 | J18: =IF(MONTH(calls[[#This Row],[Date of Call]])<=6, YEAR(calls[[#This Row],[Date of Call]]), YEAR(calls[[#This Row],[Date of Call]])+1) -> 2023 | K18: =TEXT(calls[[#This Row],[Date of Call]],"DDDD") -> Thursday | L18: {=_xlfn.IFS(calls[[#This Row],[Duration]]<=10,"under 10 mins",calls[[#This Row],[Duration]]<=30,"10 to 30mins",calls[[#This Row],[Duration]]<=60,"60 to 30mins",calls[[#This Row],[Duration]]<=120,"1 to 2hrs",TRUE,"More than 2 hrs")} -> 1 to 2hrs | M18: =ROUND(calls[[#This Row],[Satisfaction Rating]],0) -> 4 | N18: =COUNTIF(calls[Customer ID], calls[[#This Row],[Customer ID]]) -> 72 | O18: =SUMIF(calls[Customer ID], calls[[#This Row],[Customer ID]], calls[Purchase Amount]) -> 6242 | P18: =calls[[#This Row],[call count]]/calls[[#This Row],[Purchase Amount]] -> 0.36923077 | Q18: =COUNTIF(calls[Customer ID],calls[[#This Row],[Customer ID]]) -> 72 | R18: =calls[[#This Row],[call count]]/calls[[#This Row],[Purchase Amount]] -> 0.36923077 | W18: C0011 | X18: Female | Y18: 30 | Z18: Cincinnati
A19: Call_7288 | B19: C0009 | C19: 28 | D19: R03 | E19: 44931 | F19: 28 | G19: =AVERAGEIF(calls[Representative], calls[[#This Row],[Representative]], calls[Satisfaction Rating]) -> 3.8589372 | H19: =IF(AVERAGEIF(calls[Representative],calls[[#This Row],[Representative]],calls[Satisfaction Rating])<3.5,"Needs Training","OK") -> OK | I19: 3.8 | J19: =IF(MONTH(calls[[#This Row],[Date of Call]])<=6, YEAR(calls[[#This Row],[Date of Call]]), YEAR(calls[[#This Row],[Date of Call]])+1) -> 2023 | K19: =TEXT(calls[[#This Row],[Date of Call]],"DDDD") -> Thursday | L19: {=_xlfn.IFS(calls[[#This Row],[Duration]]<=10,"under 10 mins",calls[[#This Row],[Duration]]<=30,"10 to 30mins",calls[[#This Row],[Duration]]<=60,"60 to 30mins",calls[[#This Row],[Duration]]<=120,"1 to 2hrs",TRUE,"More than 2 hrs")} -> 10 to 30mins | M19: =ROUND(calls[[#This Row],[Satisfaction Rating]],0) -> 4 | N19: =COUNTIF(calls[Customer ID], calls[[#This Row],[Customer ID]]) -> 69 | O19: =SUMIF(calls[Customer ID], calls[[#This Row],[Customer ID]], calls[Purchase Amount]) -> 6601 | P19: =calls[[#This Row],[call count]]/calls[[#This Row],[Purchase Amount]] -> 2.4642857 | Q19: =COUNTIF(calls[Customer ID],calls[[#This Row],[Customer ID]]) -> 69 | R19: =calls[[#This Row],[call count]]/calls[[#This Row],[Purchase Amount]] -> 2.4642857 | W19: C0012 | X19: Female | Y19: 28 | Z19: Cincinnati
... A21: Call_7290 | B21: C0006 | C21: 48 | D21: R05 | E21: 44932 | F21: 30 | G21: =AVERAGEIF(calls[Representative], calls[[#This Row],[Representative]], calls[Satisfaction Rating]) -> 3.8825 | H21: =IF(AVERAGEIF(calls[Representative],calls[[#This Row],[Representative]],calls[Satisfaction Rating])<3.5,"Needs Training","OK") -> OK | I21: 4.4 | J21: =IF(MONTH(calls[[#This Row],[Date of Call]])<=6, YEAR(calls[[#This Row],[Date of Call]]), YEAR(calls[[#This Row],[Date of Call]])+1) -> 2023 | K21: =TEXT(calls[[#This Row],[Date of Call]],"DDDD") -> Friday | L21: {=_xlfn.IFS(calls[[#This Row],[Duration]]<=10,"under 10 mins",calls[[#This Row],[Duration]]<=30,"10 to 30mins",calls[[#This Row],[Duration]]<=60,"60 to 30mins",calls[[#This Row],[Duration]]<=120,"1 to 2hrs",TRUE,"More than 2 hrs")} -> 60 to 30mins | M21: =ROUND(calls[[#This Row],[Satisfaction Rating]],0) -> 4 | N21: =COUNTIF(calls[Customer ID], calls[[#This Row],[Customer ID]]) -> 62 | O21: =SUMIF(calls[Customer ID], calls[[#This Row],[Customer ID]], calls[Purchase Amount]) -> 6176 | P21: =calls[[#This Row],[call count]]/calls[[#This Row],[Purchase Amount]] -> 2.0666667 | Q21: =COUNTIF(calls[Customer ID],calls[[#This Row],[Customer ID]]) -> 62 | R21: =calls[[#This Row],[call count]]/calls[[#This Row],[Purchase Amount]] -> 2.0666667 | W21: C0014 | X21: Female | Y21: 38 | Z21: Columbus
A22: Call_7291 | B22: C0004 | C22: 128 | D22: R05 | E22: 44932 | F22: 72 | G22: =AVERAGEIF(calls[Representative], calls[[#This Row],[Representative]], calls[Satisfaction Rating]) -> 3.8825 | H22: =IF(AVERAGEIF(calls[Representative],calls[[#This Row],[Representative]],calls[Satisfaction Rating])<3.5,"Needs Training","OK") -> OK | I22: 5 | J22: =IF(MONTH(calls[[#This Row],[Date of Call]])<=6, YEAR(calls[[#This Row],[Date of Call]]), YEAR(calls[[#This Row],[Date of Call]])+1) -> 2023 | K22: =TEXT(calls[[#This Row],[Date of Call]],"DDDD") -> Friday | L22: {=_xlfn.IFS(calls[[#This Row],[Duration]]<=10,"under 10 mins",calls[[#This Row],[Duration]]<=30,"10 to 30mins",calls[[#This Row],[Duration]]<=60,"60 to 30mins",calls[[#This Row],[Duration]]<=120,"1 to 2hrs",TRUE,"More than 2 hrs")} -> More than 2 hrs | M22: =ROUND(calls[[#This Row],[Satisfaction Rating]],0) -> 5 | N22: =COUNTIF(calls[Customer ID], calls[[#This Row],[Customer ID]]) -> 82 | O22: =SUMIF(calls[Customer ID], calls[[#This Row],[Customer ID]], calls[Purchase Amount]) -> 7689 | P22: =calls[[#This Row],[call count]]/calls[[#This Row],[Purchase Amount]] -> 1.1388889 | Q22: =COUNTIF(calls[Customer ID],calls[[#This Row],[Customer ID]]) -> 82 | R22: =calls[[#This Row],[call count]]/calls[[#This Row],[Purchase Amount]] -> 1.1388889
A23: Call_7292 | B23: C0004 | C23: 38 | D23: R04 | E23: 44933 | F23: 92 | G23: =AVERAGEIF(calls[Representative], calls[[#This Row],[Representative]], calls[Satisfaction Rating]) -> 3.8973118 | H23: =IF(AVERAGEIF(calls[Representative],calls[[#This Row],[Representative]],calls[Satisfaction Rating])<3.5,"Needs Training","OK") -> OK | I23: 4.9 | J23: =IF(MONTH(calls[[#This Row],[Date of Call]])<=6, YEAR(calls[[#This Row],[Date of Call]]), YEAR(calls[[#This Row],[Date of Call]])+1) -> 2023 | K23: =TEXT(calls[[#This Row],[Date of Call]],"DDDD") -> Saturday | L23: {=_xlfn.IFS(calls[[#This Row],[Duration]]<=10,"under 10 mins",calls[[#This Row],[Duration]]<=30,"10 to 30mins",calls[[#This Row],[Duration]]<=60,"60 to 30mins",calls[[#This Row],[Duration]]<=120,"1 to 2hrs",TRUE,"More than 2 hrs")} -> 60 to 30mins | M23: =ROUND(calls[[#This Row],[Satisfaction Rating]],0) -> 5 | N23: =COUNTIF(calls[Customer ID], calls[[#This Row],[Customer ID]]) -> 82 | O23: =SUMIF(calls[Customer ID], calls[[#This Row],[Customer ID]], calls[Purchase Amount]) -> 7689 | P23: =calls[[#This Row],[call count]]/calls[[#This Row],[Purchase Amount]] -> 0.89130435 | Q23: =COUNTIF(calls[Customer ID],calls[[#This Row],[Customer ID]]) -> 82 | R23: =calls[[#This Row],[call count]]/calls[[#This Row],[Purchase Amount]] -> 0.89130435
A24: Call_7293 | B24: C0003 | C24: 67 | D24: R04 | E24: 44934 | F24: 165 | G24: =AVERAGEIF(calls[Representative], calls[[#This Row],[Representative]], calls[Satisfaction Rating]) -> 3.8973118 | H24: =IF(AVERAGEIF(calls[Representative],calls[[#This Row],[Representative]],calls[Satisfaction Rating])<3.5,"Needs Training","OK") -> OK | I24: 4.5 | J24: =IF(MONTH(calls[[#This Row],[Date of Call]])<=6, YEAR(calls[[#This Row],[Date of Call]]), YEAR(calls[[#This Row],[Date of Call]])+1) -> 2023 | K24: =TEXT(calls[[#This Row],[Date of Call]],"DDDD") -> Sunday | L24: {=_xlfn.IFS(calls[[#This Row],[Duration]]<=10,"under 10 mins",calls[[#This Row],[Duration]]<=30,"10 to 30mins",calls[[#This Row],[Duration]]<=60,"60 to 30mins",calls[[#This Row],[Duration]]<=120,"1 to 2hrs",TRUE,"More than 2 hrs")} -> 1 to 2hrs | M24: =ROUND(calls[[#This Row],[Satisfaction Rating]],0) -> 5 | N24: =COUNTIF(calls[Customer ID], calls[[#This Row],[Customer ID]]) -> 50 | O24: =SUMIF(calls[Customer ID], calls[[#This Row],[Customer ID]], calls[Purchase Amount]) -> 4804 | P24: =calls[[#This Row],[call count]]/calls[[#This Row],[Purchase Amount]] -> 0.3030303 | Q24: =COUNTIF(calls[Customer ID],calls[[#This Row],[Customer ID]]) -> 50 | R24: =calls[[#This Row],[call count]]/calls[[#This Row],[Purchase Amount]] -> 0.3030303
A25: Call_7294 | B25: C0015 | C25: 58 | D25: R02 | E25: 44934 | F25: 140 | G25: =AVERAGEIF(calls[Representative], calls[[#This Row],[Representative]], calls[Satisfaction Rating]) -> 3.8706422 | H25: =IF(AVERAGEIF(calls[Representative],calls[[#This Row],[Representative]],calls[Satisfaction Rating])<3.5,"Needs Training","OK") -> OK | I25: 2.1 | J25: =IF(MONTH(calls[[#This Row],[Date of Call]])<=6, YEAR(calls[[#This Row],[Date of Call]]), YEAR(calls[[#This Row],[Date of Call]])+1) -> 2023 | K25: =TEXT(calls[[#This Row],[Date of Call]],"DDDD") -> Sunday | L25: {=_xlfn.IFS(calls[[#This Row],[Duration]]<=10,"under 10 mins",calls[[#This Row],[Duration]]<=30,"10 to 30mins",calls[[#This Row],[Duration]]<=60,"60 to 30mins",calls[[#This Row],[Duration]]<=120,"1 to 2hrs",TRUE,"More than 2 hrs")} -> 60 to 30mins | M25: =ROUND(calls[[#This Row],[Satisfaction Rating]],0) -> 2 | N25: =COUNTIF(calls[Customer ID], calls[[#This Row],[Customer ID]]) -> 59 | O25: =SUMIF(calls[Customer ID], calls[[#This Row],[Customer ID]], calls[Purchase Amount]) -> 6518 | P25: =calls[[#This Row],[call count]]/calls[[#This Row],[Purchase Amount]] -> 0.42142857 | Q25: =COUNTIF(calls[Customer ID],calls[[#This Row],[Customer ID]]) -> 59 | R25: =calls[[#This Row],[call count]]/calls[[#This Row],[Purchase Amount]] -> 0.42142857
A26: Call_7295 | B26: C0010 | C26: 54 | D26: R01 | E26: 44934 | F26: 111 | G26: =AVERAGEIF(calls[Representative], calls[[#This Row],[Representative]], calls[Satisfaction Rating]) -> 3.9227513 | H26: =IF(AVERAGEIF(calls[Representative],calls[[#This Row],[Representative]],calls[Satisfaction Rating])<3.5,"Needs Training","OK") -> OK | I26: 3.3 | J26: =IF(MONTH(calls[[#This Row],[Date of Call]])<=6, YEAR(calls[[#This Row],[Date of Call]]), YEAR(calls[[#This Row],[Date of Call]])+1) -> 2023 | K26: =TEXT(calls[[#This Row],[Date of Call]],"DDDD") -> Sunday | L26: {=_xlfn.IFS(calls[[#This Row],[Duration]]<=10,"under 10 mins",calls[[#This Row],[Duration]]<=30,"10 to 30mins",calls[[#This Row],[Duration]]<=60,"60 to 30mins",calls[[#This Row],[Duration]]<=120,"1 to 2hrs",TRUE,"More than 2 hrs")} -> 60 to 30mins | M26: =ROUND(calls[[#This Row],[Satisfaction Rating]],0) -> 3 | N26: =COUNTIF(calls[Customer ID], calls[[#This Row],[Customer ID]]) -> 72 | O26: =SUMIF(calls[Customer ID], calls[[#This Row],[Customer ID]], calls[Purchase Amount]) -> 6242 | P26: =calls[[#This Row],[call count]]/calls[[#This Row],[Purchase Amount]] -> 0.64864865 | Q26: =COUNTIF(calls[Customer ID],calls[[#This Row],[Customer ID]]) -> 72 | R26: =calls[[#This Row],[call count]]/calls[[#This Row],[Purchase Amount]] -> 0.64864865
A27: Call_7296 | B27: C0012 | C27: 28 | D27: R05 | E27: 44935 | F27: 63 | G27: =AVERAGEIF(calls[Representative], calls[[#This Row],[Representative]], calls[Satisfaction Rating]) -> 3.8825 | H27: =IF(AVERAGEIF(calls[Representative],calls[[#This Row],[Representative]],calls[Satisfaction Rating])<3.5,"Needs Training","OK") -> OK | I27: 4.1 | J27: =IF(MONTH(calls[[#This Row],[Date of Call]])<=6, YEAR(calls[[#This Row],[Date of Call]]), YEAR(calls[[#This Row],[Date of Call]])+1) -> 2023 | K27: =TEXT(calls[[#This Row],[Date of Call]],"DDDD") -> Monday | L27: {=_xlfn.IFS(calls[[#This Row],[Duration]]<=10,"under 10 mins",calls[[#This Row],[Duration]]<=30,"10 to 30mins",calls[[#This Row],[Duration]]<=60,"60 to 30mins",calls[[#This Row],[Duration]]<=120,"1 to 2hrs",TRUE,"More than 2 hrs")} -> 10 to 30mins | M27: =ROUND(calls[[#This Row],[Satisfaction Rating]],0) -> 4 | N27: =COUNTIF(calls[Customer ID], calls[[#This Row],[Customer ID]]) -> 70 | O27: =SUMIF(calls[Customer ID], calls[[#This Row],[Customer ID]], calls[Purchase Amount]) -> 6819 | P27: =calls[[#This Row],[call count]]/calls[[#This Row],[Purchase Amount]] -> 1.1111111 | Q27: =COUNTIF(calls[Customer ID],calls[[#This Row],[Customer ID]]) -> 70 | R27: =calls[[#This Row],[call count]]/calls[[#This Row],[Purchase Amount]] -> 1.1111111
A28: Call_7297 | B28: C0002 | C28: 73 | D28: R05 | E28: 44935 | F28: 80 | G28: =AVERAGEIF(calls[Representative], calls[[#This Row],[Representative]], calls[Satisfaction Rating]) -> 3.8825 | H28: =IF(AVERAGEIF(calls[Representative],calls[[#This Row],[Representative]],calls[Satisfaction Rating])<3.5,"Needs Training","OK") -> OK | I28: 4.2 | J28: =IF(MONTH(calls[[#This Row],[Date of Call]])<=6, YEAR(calls[[#This Row],[Date of Call]]), YEAR(calls[[#This Row],[Date of Call]])+1) -> 2023 | K28: =TEXT(calls[[#This Row],[Date of Call]],"DDDD") -> Monday | L28: {=_xlfn.IFS(calls[[#This Row],[Duration]]<=10,"under 10 mins",calls[[#This Row],[Duration]]<=30,"10 to 30mins",calls[[#This Row],[Duration]]<=60,"60 to 30mins",calls[[#This Row],[Duration]]<=120,"1 to 2hrs",TRUE,"More than 2 hrs")} -> 1 to 2hrs | M28: =ROUND(calls[[#This Row],[Satisfaction Rating]],0) -> 4 | N28: =COUNTIF(calls[Customer ID], calls[[#This Row],[Customer ID]]) -> 63 | O28: =SUMIF(calls[Customer ID], calls[[#This Row],[Customer ID]], calls[Purchase Amount]) -> 5634 | P28: =calls[[#This Row],[call count]]/calls[[#This Row],[Purchase Amount]] -> 0.7875 | Q28: =COUNTIF(calls[Customer ID],calls[[#This Row],[Customer ID]]) -> 63 | R28: =calls[[#This Row],[call count]]/calls[[#This Row],[Purchase Amount]] -> 0.7875
A29: Call_7298 | B29: C0011 | C29: 81 | D29: R05 | E29: 44936 | F29: 50 | G29: =AVERAGEIF(calls[Representative], calls[[#This Row],[Representative]], calls[Satisfaction Rating]) -> 3.8825 | H29: =IF(AVERAGEIF(calls[Representative],calls[[#This Row],[Representative]],calls[Satisfaction Rating])<3.5,"Needs Training","OK") -> OK | I29: 4.6 | J29: =IF(MONTH(calls[[#This Row],[Date of Call]])<=6, YEAR(calls[[#This Row],[Date of Call]]), YEAR(calls[[#This Row],[Date of Call]])+1) -> 2023 | K29: =TEXT(calls[[#This Row],[Date of Call]],"DDDD") -> Tuesday | L29: {=_xlfn.IFS(calls[[#This Row],[Duration]]<=10,"under 10 mins",calls[[#This Row],[Duration]]<=30,"10 to 30mins",calls[[#This Row],[Duration]]<=60,"60 to 30mins",calls[[#This Row],[Duration]]<=120,"1 to 2hrs",TRUE,"More than 2 hrs")} -> 1 to 2hrs | M29: =ROUND(calls[[#This Row],[Satisfaction Rating]],0) -> 5 | N29: =COUNTIF(calls[Customer ID], calls[[#This Row],[Customer ID]]) -> 74 | O29: =SUMIF(calls[Customer ID], calls[[#This Row],[Customer ID]], calls[Purchase Amount]) -> 6749 | P29: =calls[[#This Row],[call count]]/calls[[#This Row],[Purchase Amount]] -> 1.48 | Q29: =COUNTIF(calls[Customer ID],calls[[#This Row],[Customer ID]]) -> 74 | R29: =calls[[#This Row],[call count]]/calls[[#This Row],[Purchase Amount]] -> 1.48
A30: Call_7299 | B30: C0009 | C30: 31 | D30: R04 | E30: 44936 | F30: 123 | G30: =AVERAGEIF(calls[Representative], calls[[#This Row],[Representative]], calls[Satisfaction Rating]) -> 3.8973118 | H30: =IF(AVERAGEIF(calls[Representative],calls[[#This Row],[Representative]],calls[Satisfaction Rating])<3.5,"Needs Training","OK") -> OK | I30: 2.9 | J30: =IF(MONTH(calls[[#This Row],[Date of Call]])<=6, YEAR(calls[[#This Row],[Date of Call]]), YEAR(calls[[#This Row],[Date of Call]])+1) -> 2023 | K30: =TEXT(calls[[#This Row],[Date of Call]],"DDDD") -> Tuesday | L30: {=_xlfn.IFS(calls[[#This Row],[Duration]]<=10,"under 10 mins",calls[[#This Row],[Duration]]<=30,"10 to 30mins",calls[[#This Row],[Duration]]<=60,"60 to 30mins",calls[[#This Row],[Duration]]<=120,"1 to 2hrs",TRUE,"More than 2 hrs")} -> 60 to 30mins | M30: =ROUND(calls[[#This Row],[Satisfaction Rating]],0) -> 3 | N30: =COUNTIF(calls[Customer ID], calls[[#This Row],[Customer ID]]) -> 69 | O30: =SUMIF(calls[Customer ID], calls[[#This Row],[Customer ID]], calls[Purchase Amount]) -> 6601 | P30: =calls[[#This Row],[call count]]/calls[[#This Row],[Purchase Amount]] -> 0.56097561 | Q30: =COUNTIF(calls[Customer ID],calls[[#This Row],[Customer ID]]) -> 69 | R30: =calls[[#This Row],[call count]]/calls[[#This Row],[Purchase Amount]] -> 0.56097561
A31: Call_7300 | B31: C0015 | C31: 155 | D31: R01 | E31: 44936 | F31: 110 | G31: =AVERAGEIF(calls[Representative], calls[[#This Row],[Representative]], calls[Satisfaction Rating]) -> 3.9227513 | H31: =IF(AVERAGEIF(calls[Representative],calls[[#This Row],[Representative]],calls[Satisfaction Rating])<3.5,"Needs Training","OK") -> OK | I31: 4.8 | J31: =IF(MONTH(calls[[#This Row],[Date of Call]])<=6, YEAR(calls[[#This Row],[Date of Call]]), YEAR(calls[[#This Row],[Date of Call]])+1) -> 2023 | K31: =TEXT(calls[[#This Row],[Date of Call]],"DDDD") -> Tuesday | L31: {=_xlfn.IFS(calls[[#This Row],[Duration]]<=10,"under 10 mins",calls[[#This Row],[Duration]]<=30,"10 to 30mins",calls[[#This Row],[Duration]]<=60,"60 to 30mins",calls[[#This Row],[Duration]]<=120,"1 to 2hrs",TRUE,"More than 2 hrs")} -> More than 2 hrs | M31: =ROUND(calls[[#This Row],[Satisfaction Rating]],0) -> 5 | N31: =COUNTIF(calls[Customer ID], calls[[#This Row],[Customer ID]]) -> 59 | O31: =SUMIF(calls[Customer ID], calls[[#This Row],[Customer ID]], calls[Purchase Amount]) -> 6518 | P31: =calls[[#This Row],[call count]]/calls[[#This Row],[Purchase Amount]] -> 0.53636364 | Q31: =COUNTIF(calls[Customer ID],calls[[#This Row],[Customer ID]]) -> 59 | R31: =calls[[#This Row],[call count]]/calls[[#This Row],[Purchase Amount]] -> 0.53636364
A32: Call_7301 | B32: C0009 | C32: 80 | D32: R05 | E32: 44936 | F32: 140 | G32: =AVERAGEIF(calls[Representative], calls[[#This Row],[Representative]], calls[Satisfaction Rating]) -> 3.8825 | H32: =IF(AVERAGEIF(calls[Representative],calls[[#This Row],[Representative]],calls[Satisfaction Rating])<3.5,"Needs Training","OK") -> OK | I32: 4.2 | J32: =IF(MONTH(calls[[#This Row],[Date of Call]])<=6, YEAR(calls[[#This Row],[Date of Call]]), YEAR(calls[[#This Row],[Date of Call]])+1) -> 2023 | K32: =TEXT(calls[[#This Row],[Date of Call]],"DDDD") -> Tuesday | L32: {=_xlfn.IFS(calls[[#This Row],[Duration]]<=10,"under 10 mins",calls[[#This Row],[Duration]]<=30,"10 to 30mins",calls[[#This Row],[Duration]]<=60,"60 to 30mins",calls[[#This Row],[Duration]]<=120,"1 to 2hrs",TRUE,"More than 2 hrs")} -> 1 to 2hrs | M32: =ROUND(calls[[#This Row],[Satisfaction Rating]],0) -> 4 | N32: =COUNTIF(calls[Customer ID], calls[[#This Row],[Customer ID]]) -> 69 | O32: =SUMIF(calls[Customer ID], calls[[#This Row],[Customer ID]], calls[Purchase Amount]) -> 6601 | P32: =calls[[#This Row],[call count]]/calls[[#This Row],[Purchase Amount]] -> 0.49285714 | Q32: =COUNTIF(calls[Customer ID],calls[[#This Row],[Customer ID]]) -> 69 | R32: =calls[[#This Row],[call count]]/calls[[#This Row],[Purchase Amount]] -> 0.49285714
A33: Call_7302 | B33: C0011 | C33: 82 | D33: R05 | E33: 44938 | F33: 42 | G33: =AVERAGEIF(calls[Representative], calls[[#This Row],[Representative]], calls[Satisfaction Rating]) -> 3.8825 | H33: =IF(AVERAGEIF(calls[Representative],calls[[#This Row],[Representative]],calls[Satisfaction Rating])<3.5,"Needs Training","OK") -> OK | I33: 3.7 | J33: =IF(MONTH(calls[[#This Row],[Date of Call]])<=6, YEAR(calls[[#This Row],[Date of Call]]), YEAR(calls[[#This Row],[Date of Call]])+1) -> 2023 | K33: =TEXT(calls[[#This Row],[Date of Call]],"DDDD") -> Thursday | L33: {=_xlfn.IFS(calls[[#This Row],[Duration]]<=10,"under 10 mins",calls[[#This Row],[Duration]]<=30,"10 to 30mins",calls[[#This Row],[Duration]]<=60,"60 to 30mins",calls[[#This Row],[Duration]]<=120,"1 to 2hrs",TRUE,"More than 2 hrs")} -> 1 to 2hrs | M33: =ROUND(calls[[#This Row],[Satisfaction Rating]],0) -> 4 | N33: =COUNTIF(calls[Customer ID], calls[[#This Row],[Customer ID]]) -> 74 | O33: =SUMIF(calls[Customer ID], calls[[#This Row],[Customer ID]], calls[Purchase Amount]) -> 6749 | P33: =calls[[#This Row],[call count]]/calls[[#This Row],[Purchase Amount]] -> 1.7619048 | Q33: =COUNTIF(calls[Customer ID],calls[[#This Row],[Customer ID]]) -> 74 | R33: =calls[[#This Row],[call count]]/calls[[#This Row],[Purchase Amount]] -> 1.7619048
